---
title: 一文搞定Promise
date: 2024-2-20 17:34:20
tags:
- 前端学习计划
- Promise
- 一文搞定面试
- 手写源码
categories: 
- 一文搞定面试
---

#### promise

1. 调用`resolve`或`reject`并不会终结 Promise 的参数函数的执行。

2. Promise 对象的错误具有“冒泡”性质，会一直向后传递，直到被捕获为止。也就是说，错误总是会被下一个`catch`语句捕获。一般来说，不要在`then()`方法里面定义 Reject 状态的回调函数（即`then`的第二个参数），总是使用`catch`方法。

  Promise 会吃掉错误

3. promise 实现ajax 

```javascript
const getJSON = function(url) {
  const promise = new Promise(function(resolve, reject){
    const handler = function() {
      if (this.readyState !== 4) {
        return;
      }
      if (this.status === 200) {
        resolve(this.response);
      } else {
        reject(new Error(this.statusText));
      }
    };
    const client = new XMLHttpRequest();
    client.open("GET", url);
    client.onreadystatechange = handler;
    client.responseType = "json";
    client.setRequestHeader("Accept", "application/json");
    client.send();

  });

  return promise;
};

getJSON("/posts.json").then(function(json) {
  console.log('Contents: ' + json);
}, function(error) {
  console.error('出错了', error);
});
```

注意，如果作为参数的 Promise 实例，自己定义了`catch`方法，那么它一旦被`rejected`，并不会触发`Promise.all()`的`catch`方法。

```javascript
const p1 = new Promise((resolve, reject) => {
  resolve('hello');
})
.then(result => result)
.catch(e => e);

const p2 = new Promise((resolve, reject) => {
  throw new Error('报错了');
})
.then(result => result)
.catch(e => e);

Promise.all([p1, p2])
.then(result => console.log(result))
.catch(e => console.log(e));
// ["hello", Error: 报错了]
```

上面代码中，`p1`会`resolved`，`p2`首先会`rejected`，但是`p2`有自己的`catch`方法，该方法返回的是一个新的 Promise 实例，`p2`指向的实际上是这个实例。该实例执行完`catch`方法后，也会变成`resolved`，导致`Promise.all()`方法参数里面的两个实例都会`resolved`，因此会调用`then`方法指定的回调函数，而不会调用`catch`方法指定的回调函数。

**allSettled** 不管reject 还是 fulfiiled 只要全执行完就返回result 固

**any** 和**race** 区别为 any一个reject 不停止运行 全reject 才返回reject race就是出现第一个fulfilled 或者第一个rejected就包装成fulfilled或rejected

##### 